Workbook

Sheet TT
A1: Under 18 | K1: Above 18
A2: Sr. No | B2: Name | C2: Age | D2: Gender | E2: Blood Group | F2: Singles | G2: Doubles | H2: Mixed Doubles | I2: Paid | K2: Sr. No | L2: Name | M2: Age | N2: Gender | O2: Blood Group | P2: Single | Q2: Doubles | R2: Mixed Doubles | S2: Paid
A3: =ROW(A1) -> 1 | B3: P001 | C3: 8 | D3: Male | F3: Yes | K3: =ROW(K1) -> 1 | L3: P020 | M3: 25 | N3: Male | P3: Yes | Q3: Yes
A4: =ROW(A2) -> 2 | B4: P002 | C4: 10 | D4: Male | F4: Yes | K4: =ROW(K2) -> 2 | L4: P022 | M4: 41 | N4: Male | O4: B+ | P4: Yes
A5: =ROW(A3) -> 3 | B5: P003 | C5: 15 | D5: Female | E5: O+ | F5: Yes | G5: Yes | K5: =ROW(K3) -> 3 | L5: P023 | M5: 45 | N5: Male | O5: O+ | P5: Yes
A6: =ROW(A4) -> 4 | B6: P004 | C6: 16 | D6: Female | F6: Yes | G6: Yes | K6: =ROW(K4) -> 4 | L6: P024 | M6: 36 | N6: Male | P6: Yes | Q6: Yes
A7: =ROW(A5) -> 5 | B7: P005 | C7: 15 | D7: Male | E7: O+ | F7: Yes | G7: Yes | K7: =ROW(K5) -> 5 | L7: P025 | M7: 37 | N7: Male | P7: Yes | Q7: Yes
A8: =ROW(A6) -> 6 | B8: P006 | C8: 12 | D8: Male | E8: A+ | F8: Yes | K8: =ROW(K6) -> 6 | L8: P026 | M8: 50 | N8: Male | P8: Yes
A9: 7 | B9: P007 | C9: 16 | D9: Male | K9: =ROW(K7) -> 7 | L9: P027 | M9: 22 | N9: Female | O9: B+ | P9: Yes | Q9: Yes | R9: Yes
A10: 8 | B10: P008 | C10: 17 | D10: Male | E10: AB+ | F10: Yes | K10: =ROW(K8) -> 8 | L10: P028 | M10: 27 | N10: Female | O10: B+ | P10: Yes | Q10: Yes
A11: 9 | B11: P009 | C11: 17 | D11: Male | K11: =ROW(K10) -> 10 | L11: P029 | M11: 31 | N11: Male | P11: Yes | S11: Paid
A12: 10 | B12: P010 | C12: 15 | D12: Male | K12: =ROW(K11) -> 11 | L12: P030 | M12: 19 | N12: Male | O12: O+ | P12: Yes | Q12: Yes
A13: 11 | B13: P011 | C13: 15 | D13: Male | K13: =ROW(K12) -> 12 | L13: P031 | M13: 27 | N13: Male
A14: 12 | B14: P012 | C14: 15 | D14: Female | E14: O+ | K14: 13 | L14: P032 | M14: 25 | N14: Male
A15: 13 | B15: P013 | C15: 8 | D15: Male | K15: 14 | L15: P033 | M15: 26 | N15: Male
A16: 14 | B16: P014 | C16: 17 | D16: Male | K16: =K15+1 -> 15 | L16: P034 | M16: 26 | N16: Male
A17: 15 | B17: P015 | C17: 9 | D17: Female | K17: =K16+1 -> 16 | L17: P035 | M17: 38 | N17: Male
A18: 16 | B18: P016 | C18: 12 | D18: Male | K18: =K17+1 -> 17 | L18: P036 | M18: 18 | N18: Male | O18: AB+ | P18: Yes
A19: 17 | B19: P017 | C19: 7 | D19: Male | K19: =K18+1 -> 18 | L19: P019 | M19: 18 | N19: Male
A20: 18 | B20: P018 | C20: 7 | D20: Male | K20: =K19+1 -> 19 | L20: P037 | M20: 24 | N20: Male
A21: 19 | B21: P019 | C21: 18 | D21: Male | K21: =K20+1 -> 20 | L21: P038 | M21: 19 | N21: Male
K22: =K21+1 -> 21 | L22: P039 | M22: 42 | N22: Male
K23: =K22+1 -> 22 | L23: P040 | M23: 18 | N23: Female
K24: =K23+1 -> 23 | L24: P041 | M24: 20 | N24: Male
K25: =K24+1 -> 24 | L25: P042 | M25: 34 | N25: Male | O25: A+
K26: 25 | L26: P043 | N26: Male
K27: 26 | L27: P026 | M27: 50 | N27: Male | O27: O+
K28: 27 | L28: P044 | N28: Male
K29: 28 | L29: P045 | N29: Male
K30: 29 | L30: P046 | M30: 40 | N30: Male | O30: B+
K31: 30 | L31: P047 | M31: 40 | N31: Male

Sheet Badminton
A1: Under 18 | K1: Above 18
A2: Sr. No | B2: Name | C2: Age | D2: Gender | E2: Blood Group | F2: Singles | G2: Doubles | H2: Mixed Doubles | I2: Paid | K2: Sr. No | L2: Name | M2: Age | N2: Gender | O2: Blood Group | P2: Single | Q2: Doubles | R2: Mixed Doubles | S2: Paid
A3: =ROW(A1) -> 1 | B3: P008 | C3: 17 | D3: Male | E3: AB+ | F3: Yes | K3: =ROW(K1) -> 1 | L3: P025 | M3: 37 | N3: Male | P3: Yes | Q3: Yes
A4: =ROW(A2) -> 2 | B4: P005 | C4: 15 | D4: Male | E4: O+ | F4: Yes | G4: Yes | K4: =ROW(K2) -> 2 | L4: P054 | M4: 35 | N4: Female | P4: Yes
A5: =ROW(A3) -> 3 | B5: P006 | C5: 12 | D5: Male | E5: A+ | F5: Yes | K5: =ROW(K3) -> 3 | L5: P055 | M5: 36 | N5: Male | P5: Yes | Q5: Yes
A6: =ROW(A4) -> 4 | B6: P050 | C6: 15 | D6: Male | E6: A+ | G6: Yes | K6: =ROW(K4) -> 4 | L6: P056 | N6: Male | P6: Yes
A7: =ROW(A5) -> 5 | B7: P049 | C7: 12 | D7: Female | E7: B+ | K7: =ROW(K5) -> 5 | L7: P027 | M7: 22 | N7: Female | O7: B+ | R7: Yes
A8: 6 | B8: P007 | C8: 16 | D8: Male | F8: Yes | K8: =ROW(K6) -> 6 | L8: P028 | M8: 27 | N8: Female | P8: Yes
A9: 7 | B9: P048 | C9: 12 | D9: Male | E9: A- | K9: =ROW(K7) -> 7 | L9: P057 | N9: Female | O9: B+ | P9: Yes
K10: 8 | L10: P032 | M10: 25 | N10: Male
K11: 9 | L11: P035 | M11: 39 | N11: Male
K12: 10 | L12: P033 | M12: 26 | N12: Male
K13: 11 | L13: P051 | M13: 21 | N13: Male | O13: B+
K14: 12 | L14: P058 | M14: 25 | N14: Female
K15: 13 | L15: P020 | M15: 25 | N15: Male
K16: 14 | L16: P047 | M16: 40 | N16: Male
K17: 15 | L17: P052 | M17: 24 | N17: Male | O17: AB- | P17: Yes | Q17: Yes
K18: 16 | L18: P030 | M18: 18 | N18: Male | O18: O+ | P18: Yes | Q18: Yes
K19: 17 | L19: P036 | M19: 18 | N19: Male | O19: AB+ | P19: Yes
K20: 18 | L20: P053 | M20: 40 | N20: Female | O20: A+

Sheet Consolidated Sheet
A1: Sr. No | B1: Full Name | C1: Age | D1: Gender | E1: Blood Group
A2: =ROW(A1) -> 1 | B2: =IFERROR(__xludf.DUMMYFUNCTION("IFERROR(UNIQUE(QUERY({FILTER(Badminton!B3:E1001, LEN(Badminton!B3:B1001));FILTER(Badminton!L3:O1001, LEN(Badminton!L3:L1001));FILTER(TT!B3:E1001, LEN(TT!B3:B1001));FILTER(TT!L3:O1001, LEN(TT!L3:L1001))}, ""SELECT Col1, Col2, Col3, Col4 WHERE Col1 IS NOT N"&"ULL"", 0)), """")"),"P008") -> P008 | C2: =IFERROR(__xludf.DUMMYFUNCTION("""COMPUTED_VALUE"""),17.0) -> 17 | D2: =IFERROR(__xludf.DUMMYFUNCTION("""COMPUTED_VALUE"""),"Male") -> Male | E2: =IFERROR(__xludf.DUMMYFUNCTION("""COMPUTED_VALUE"""),"AB+") -> AB+
A3: =ROW(A2) -> 2 | B3: =IFERROR(__xludf.DUMMYFUNCTION("""COMPUTED_VALUE"""),"P005") -> P005 | C3: =IFERROR(__xludf.DUMMYFUNCTION("""COMPUTED_VALUE"""),15.0) -> 15 | D3: =IFERROR(__xludf.DUMMYFUNCTION("""COMPUTED_VALUE"""),"Male") -> Male | E3: =IFERROR(__xludf.DUMMYFUNCTION("""COMPUTED_VALUE"""),"O+") -> O+
A4: =ROW(A3) -> 3 | B4: =IFERROR(__xludf.DUMMYFUNCTION("""COMPUTED_VALUE"""),"P006") -> P006 | C4: =IFERROR(__xludf.DUMMYFUNCTION("""COMPUTED_VALUE"""),12.0) -> 12 | D4: =IFERROR(__xludf.DUMMYFUNCTION("""COMPUTED_VALUE"""),"Male") -> Male | E4: =IFERROR(__xludf.DUMMYFUNCTION("""COMPUTED_VALUE"""),"A+") -> A+
A5: =ROW(A4) -> 4 | B5: =IFERROR(__xludf.DUMMYFUNCTION("""COMPUTED_VALUE"""),"P050") -> P050 | C5: =IFERROR(__xludf.DUMMYFUNCTION("""COMPUTED_VALUE"""),15.0) -> 15 | D5: =IFERROR(__xludf.DUMMYFUNCTION("""COMPUTED_VALUE"""),"Male") -> Male | E5: =IFERROR(__xludf.DUMMYFUNCTION("""COMPUTED_VALUE"""),"A+") -> A+
A6: =ROW(A5) -> 5 | B6: =IFERROR(__xludf.DUMMYFUNCTION("""COMPUTED_VALUE"""),"P049") -> P049 | C6: =IFERROR(__xludf.DUMMYFUNCTION("""COMPUTED_VALUE"""),12.0) -> 12 | D6: =IFERROR(__xludf.DUMMYFUNCTION("""COMPUTED_VALUE"""),"Female") -> Female | E6: =IFERROR(__xludf.DUMMYFUNCTION("""COMPUTED_VALUE"""),"B+") -> B+
A7: =ROW(A6) -> 6 | B7: =IFERROR(__xludf.DUMMYFUNCTION("""COMPUTED_VALUE"""),"P007") -> P007 | C7: =IFERROR(__xludf.DUMMYFUNCTION("""COMPUTED_VALUE"""),16.0) -> 16 | D7: =IFERROR(__xludf.DUMMYFUNCTION("""COMPUTED_VALUE"""),"Male") -> Male
A8: =ROW(A7) -> 7 | B8: =IFERROR(__xludf.DUMMYFUNCTION("""COMPUTED_VALUE"""),"P048") -> P048 | C8: =IFERROR(__xludf.DUMMYFUNCTION("""COMPUTED_VALUE"""),12.0) -> 12 | D8: =IFERROR(__xludf.DUMMYFUNCTION("""COMPUTED_VALUE"""),"Male") -> Male | E8: =IFERROR(__xludf.DUMMYFUNCTION("""COMPUTED_VALUE"""),"A-") -> A-
A9: =ROW(A8) -> 8 | B9: =IFERROR(__xludf.DUMMYFUNCTION("""COMPUTED_VALUE"""),"P025") -> P025 | C9: =IFERROR(__xludf.DUMMYFUNCTION("""COMPUTED_VALUE"""),37.0) -> 37 | D9: =IFERROR(__xludf.DUMMYFUNCTION("""COMPUTED_VALUE"""),"Male") -> Male
A10: =ROW(A9) -> 9 | B10: =IFERROR(__xludf.DUMMYFUNCTION("""COMPUTED_VALUE"""),"P054") -> P054 | C10: =IFERROR(__xludf.DUMMYFUNCTION("""COMPUTED_VALUE"""),35.0) -> 35 | D10: =IFERROR(__xludf.DUMMYFUNCTION("""COMPUTED_VALUE"""),"Female") -> Female
A11: =ROW(A10) -> 10 | B11: =IFERROR(__xludf.DUMMYFUNCTION("""COMPUTED_VALUE"""),"P055") -> P055 | C11: =IFERROR(__xludf.DUMMYFUNCTION("""COMPUTED_VALUE"""),36.0) -> 36 | D11: =IFERROR(__xludf.DUMMYFUNCTION("""COMPUTED_VALUE"""),"Male") -> Male
A12: =ROW(A11) -> 11 | B12: =IFERROR(__xludf.DUMMYFUNCTION("""COMPUTED_VALUE"""),"P056") -> P056 | D12: =IFERROR(__xludf.DUMMYFUNCTION("""COMPUTED_VALUE"""),"Male ") -> Male
A13: =ROW(A12) -> 12 | B13: =IFERROR(__xludf.DUMMYFUNCTION("""COMPUTED_VALUE"""),"P027") -> P027 | C13: =IFERROR(__xludf.DUMMYFUNCTION("""COMPUTED_VALUE"""),22.0) -> 22 | D13: =IFERROR(__xludf.DUMMYFUNCTION("""COMPUTED_VALUE"""),"Female") -> Female | E13: =IFERROR(__xludf.DUMMYFUNCTION("""COMPUTED_VALUE"""),"B+") -> B+
A14: =ROW(A13) -> 13 | B14: =IFERROR(__xludf.DUMMYFUNCTION("""COMPUTED_VALUE"""),"P028") -> P028 | C14: =IFERROR(__xludf.DUMMYFUNCTION("""COMPUTED_VALUE"""),27.0) -> 27 | D14: =IFERROR(__xludf.DUMMYFUNCTION("""COMPUTED_VALUE"""),"Female") -> Female
A15: =ROW(A14) -> 14 | B15: =IFERROR(__xludf.DUMMYFUNCTION("""COMPUTED_VALUE"""),"P057") -> P057 | D15: =IFERROR(__xludf.DUMMYFUNCTION("""COMPUTED_VALUE"""),"Female") -> Female | E15: =IFERROR(__xludf.DUMMYFUNCTION("""COMPUTED_VALUE"""),"B+") -> B+
A16: =ROW(A15) -> 15 | B16: =IFERROR(__xludf.DUMMYFUNCTION("""COMPUTED_VALUE"""),"P032") -> P032 | C16: =IFERROR(__xludf.DUMMYFUNCTION("""COMPUTED_VALUE"""),25.0) -> 25 | D16: =IFERROR(__xludf.DUMMYFUNCTION("""COMPUTED_VALUE"""),"Male") -> Male
A17: =ROW(A16) -> 16 | B17: =IFERROR(__xludf.DUMMYFUNCTION("""COMPUTED_VALUE"""),"P035") -> P035 | C17: =IFERROR(__xludf.DUMMYFUNCTION("""COMPUTED_VALUE"""),39.0) -> 39 | D17: =IFERROR(__xludf.DUMMYFUNCTION("""COMPUTED_VALUE"""),"Male") -> Male
A18: =ROW(A17) -> 17 | B18: =IFERROR(__xludf.DUMMYFUNCTION("""COMPUTED_VALUE"""),"P033") -> P033 | C18: =IFERROR(__xludf.DUMMYFUNCTION("""COMPUTED_VALUE"""),26.0) -> 26 | D18: =IFERROR(__xludf.DUMMYFUNCTION("""COMPUTED_VALUE"""),"Male") -> Male
A19: =ROW(A18) -> 18 | B19: =IFERROR(__xludf.DUMMYFUNCTION("""COMPUTED_VALUE"""),"P051") -> P051 | C19: =IFERROR(__xludf.DUMMYFUNCTION("""COMPUTED_VALUE"""),21.0) -> 21 | D19: =IFERROR(__xludf.DUMMYFUNCTION("""COMPUTED_VALUE"""),"Male") -> Male | E19: =IFERROR(__xludf.DUMMYFUNCTION("""COMPUTED_VALUE"""),"B+") -> B+
A20: =ROW(A19) -> 19 | B20: =IFERROR(__xludf.DUMMYFUNCTION("""COMPUTED_VALUE"""),"P058") -> P058 | C20: =IFERROR(__xludf.DUMMYFUNCTION("""COMPUTED_VALUE"""),25.0) -> 25 | D20: =IFERROR(__xludf.DUMMYFUNCTION("""COMPUTED_VALUE"""),"Female ") -> Female
A21: =ROW(A20) -> 20 | B21: =IFERROR(__xludf.DUMMYFUNCTION("""COMPUTED_VALUE"""),"P020") -> P020 | C21: =IFERROR(__xludf.DUMMYFUNCTION("""COMPUTED_VALUE"""),25.0) -> 25 | D21: =IFERROR(__xludf.DUMMYFUNCTION("""COMPUTED_VALUE"""),"Male") -> Male
A22: =ROW(A21) -> 21 | B22: =IFERROR(__xludf.DUMMYFUNCTION("""COMPUTED_VALUE"""),"P047") -> P047 | C22: =IFERROR(__xludf.DUMMYFUNCTION("""COMPUTED_VALUE"""),40.0) -> 40 | D22: =IFERROR(__xludf.DUMMYFUNCTION("""COMPUTED_VALUE"""),"Male") -> Male
A23: =ROW(A22) -> 22 | B23: =IFERROR(__xludf.DUMMYFUNCTION("""COMPUTED_VALUE"""),"P052") -> P052 | C23: =IFERROR(__xludf.DUMMYFUNCTION("""COMPUTED_VALUE"""),24.0) -> 24 | D23: =IFERROR(__xludf.DUMMYFUNCTION("""COMPUTED_VALUE"""),"Male") -> Male | E23: =IFERROR(__xludf.DUMMYFUNCTION("""COMPUTED_VALUE"""),"AB-") -> AB-
A24: =ROW(A23) -> 23 | B24: =IFERROR(__xludf.DUMMYFUNCTION("""COMPUTED_VALUE"""),"P030") -> P030 | C24: =IFERROR(__xludf.DUMMYFUNCTION("""COMPUTED_VALUE"""),18.0) -> 18 | D24: =IFERROR(__xludf.DUMMYFUNCTION("""COMPUTED_VALUE"""),"Male") -> Male | E24: =IFERROR(__xludf.DUMMYFUNCTION("""COMPUTED_VALUE"""),"O+") -> O+
A25: =ROW(A24) -> 24 | B25: =IFERROR(__xludf.DUMMYFUNCTION("""COMPUTED_VALUE"""),"P036") -> P036 | C25: =IFERROR(__xludf.DUMMYFUNCTION("""COMPUTED_VALUE"""),18.0) -> 18 | D25: =IFERROR(__xludf.DUMMYFUNCTION("""COMPUTED_VALUE"""),"Male") -> Male | E25: =IFERROR(__xludf.DUMMYFUNCTION("""COMPUTED_VALUE"""),"AB+") -> AB+
A26: =ROW(A25) -> 25 | B26: =IFERROR(__xludf.DUMMYFUNCTION("""COMPUTED_VALUE"""),"P053") -> P053 | C26: =IFERROR(__xludf.DUMMYFUNCTION("""COMPUTED_VALUE"""),40.0) -> 40 | D26: =IFERROR(__xludf.DUMMYFUNCTION("""COMPUTED_VALUE"""),"Female") -> Female | E26: =IFERROR(__xludf.DUMMYFUNCTION("""COMPUTED_VALUE"""),"A+") -> A+
A27: =ROW(A26) -> 26 | B27: =IFERROR(__xludf.DUMMYFUNCTION("""COMPUTED_VALUE"""),"P001") -> P001 | C27: =IFERROR(__xludf.DUMMYFUNCTION("""COMPUTED_VALUE"""),8.0) -> 8 | D27: =IFERROR(__xludf.DUMMYFUNCTION("""COMPUTED_VALUE"""),"Male") -> Male
A28: =ROW(A27) -> 27 | B28: =IFERROR(__xludf.DUMMYFUNCTION("""COMPUTED_VALUE"""),"P002") -> P002 | C28: =IFERROR(__xludf.DUMMYFUNCTION("""COMPUTED_VALUE"""),10.0) -> 10 | D28: =IFERROR(__xludf.DUMMYFUNCTION("""COMPUTED_VALUE"""),"Male") -> Male
A29: =ROW(A28) -> 28 | B29: =IFERROR(__xludf.DUMMYFUNCTION("""COMPUTED_VALUE"""),"P003") -> P003 | C29: =IFERROR(__xludf.DUMMYFUNCTION("""COMPUTED_VALUE"""),15.0) -> 15 | D29: =IFERROR(__xludf.DUMMYFUNCTION("""COMPUTED_VALUE"""),"Female") -> Female | E29: =IFERROR(__xludf.DUMMYFUNCTION("""COMPUTED_VALUE"""),"O+") -> O+
A30: =ROW(A29) -> 29 | B30: =IFERROR(__xludf.DUMMYFUNCTION("""COMPUTED_VALUE"""),"P004") -> P004 | C30: =IFERROR(__xludf.DUMMYFUNCTION("""COMPUTED_VALUE"""),16.0) -> 16 | D30: =IFERROR(__xludf.DUMMYFUNCTION("""COMPUTED_VALUE"""),"Female") -> Female
A31: =ROW(A30) -> 30 | B31: =IFERROR(__xludf.DUMMYFUNCTION("""COMPUTED_VALUE"""),"P009") -> P009 | C31: =IFERROR(__xludf.DUMMYFUNCTION("""COMPUTED_VALUE"""),17.0) -> 17 | D31: =IFERROR(__xludf.DUMMYFUNCTION("""COMPUTED_VALUE"""),"Male") -> Male
A32: =ROW(A31) -> 31 | B32: =IFERROR(__xludf.DUMMYFUNCTION("""COMPUTED_VALUE"""),"P010") -> P010 | C32: =IFERROR(__xludf.DUMMYFUNCTION("""COMPUTED_VALUE"""),15.0) -> 15 | D32: =IFERROR(__xludf.DUMMYFUNCTION("""COMPUTED_VALUE"""),"Male") -> Male
A33: =ROW(A32) -> 32 | B33: =IFERROR(__xludf.DUMMYFUNCTION("""COMPUTED_VALUE"""),"P011") -> P011 | C33: =IFERROR(__xludf.DUMMYFUNCTION("""COMPUTED_VALUE"""),15.0) -> 15 | D33: =IFERROR(__xludf.DUMMYFUNCTION("""COMPUTED_VALUE"""),"Male") -> Male
A34: =ROW(A33) -> 33 | B34: =IFERROR(__xludf.DUMMYFUNCTION("""COMPUTED_VALUE"""),"P012") -> P012 | C34: =IFERROR(__xludf.DUMMYFUNCTION("""COMPUTED_VALUE"""),15.0) -> 15 | D34: =IFERROR(__xludf.DUMMYFUNCTION("""COMPUTED_VALUE"""),"Female") -> Female | E34: =IFERROR(__xludf.DUMMYFUNCTION("""COMPUTED_VALUE"""),"O+") -> O+
A35: =ROW(A34) -> 34 | B35: =IFERROR(__xludf.DUMMYFUNCTION("""COMPUTED_VALUE"""),"P013") -> P013 | C35: =IFERROR(__xludf.DUMMYFUNCTION("""COMPUTED_VALUE"""),8.0) -> 8 | D35: =IFERROR(__xludf.DUMMYFUNCTION("""COMPUTED_VALUE"""),"Male") -> Male
A36: =ROW(A35) -> 35 | B36: =IFERROR(__xludf.DUMMYFUNCTION("""COMPUTED_VALUE"""),"P014") -> P014 | C36: =IFERROR(__xludf.DUMMYFUNCTION("""COMPUTED_VALUE"""),17.0) -> 17 | D36: =IFERROR(__xludf.DUMMYFUNCTION("""COMPUTED_VALUE"""),"Male") -> Male
A37: =ROW(A36) -> 36 | B37: =IFERROR(__xludf.DUMMYFUNCTION("""COMPUTED_VALUE"""),"P015") -> P015 | C37: =IFERROR(__xludf.DUMMYFUNCTION("""COMPUTED_VALUE"""),9.0) -> 9 | D37: =IFERROR(__xludf.DUMMYFUNCTION("""COMPUTED_VALUE"""),"Female") -> Female
A38: =ROW(A37) -> 37 | B38: =IFERROR(__xludf.DUMMYFUNCTION("""COMPUTED_VALUE"""),"P016") -> P016 | C38: =IFERROR(__xludf.DUMMYFUNCTION("""COMPUTED_VALUE"""),12.0) -> 12 | D38: =IFERROR(__xludf.DUMMYFUNCTION("""COMPUTED_VALUE"""),"Male") -> Male
A39: =ROW(A38) -> 38 | B39: =IFERROR(__xludf.DUMMYFUNCTION("""COMPUTED_VALUE"""),"P017") -> P017 | C39: =IFERROR(__xludf.DUMMYFUNCTION("""COMPUTED_VALUE"""),7.0) -> 7 | D39: =IFERROR(__xludf.DUMMYFUNCTION("""COMPUTED_VALUE"""),"Male") -> Male
A40: =ROW(A39) -> 39 | B40: =IFERROR(__xludf.DUMMYFUNCTION("""COMPUTED_VALUE"""),"P018") -> P018 | C40: =IFERROR(__xludf.DUMMYFUNCTION("""COMPUTED_VALUE"""),7.0) -> 7 | D40: =IFERROR(__xludf.DUMMYFUNCTION("""COMPUTED_VALUE"""),"Male") -> Male
...

Sheet Registration Sheet
A1: Sr. no | B1: Name | C1: Age | D1: Gender | E1: Center | F1: Blood Group | G1: TT Singles | H1: TT Doubles | I1: TT Mixed Doubles | J1: Batty Singles | K1: Batty Doubles | L1: Batty Mixed Doubles | M1: Fees | N1: Paid (Yes/ No) | O1: Amount Paid | P1: Amount Pending
A2: =ROW(A1) -> 1 | B2: P018 | C2: =VLOOKUP(B2, 'Consolidated Sheet'!B:C, 2, FALSE) -> 7 | D2: Male | E2: Margao | F2: =VLOOKUP(B2, 'Consolidated Sheet'!B:E, 4, FALSE) | G2: TRUE | H2: TRUE | I2: FALSE | J2: FALSE | K2: FALSE | L2: FALSE | M2: =COUNTIF(G2:L2, TRUE) * 100 -> 200 | N2: Yes | O2: 200 | P2: =M2-O2 -> 0
A3: =ROW(A2) -> 2 | B3: P013 | C3: =VLOOKUP(B3, 'Consolidated Sheet'!B:C, 2, FALSE) -> 8 | D3: Male | E3: Vasco | F3: =VLOOKUP(B3, 'Consolidated Sheet'!B:E, 4, FALSE) | G3: TRUE | H3: TRUE | I3: FALSE | J3: FALSE | K3: FALSE | L3: FALSE | M3: =COUNTIF(G3:L3, TRUE) * 100 -> 200 | N3: Yes | O3: 200 | P3: =M3-O3 -> 0
A4: =ROW(A3) -> 3 | B4: P015 | C4: =VLOOKUP(B4, 'Consolidated Sheet'!B:C, 2, FALSE) -> 9 | D4: Female | E4: Margao | F4: =VLOOKUP(B4, 'Consolidated Sheet'!B:E, 4, FALSE) | G4: TRUE | H4: FALSE | I4: FALSE | J4: FALSE | K4: FALSE | L4: FALSE | M4: =COUNTIF(G4:L4, TRUE) * 100 -> 100 | N4: Yes | O4: 100 | P4: =M4-O4 -> 0
A5: =ROW(A4) -> 4 | B5: P002 | C5: =VLOOKUP(B5, 'Consolidated Sheet'!B:C, 2, FALSE) -> 10 | D5: Male | E5: Margao | F5: =VLOOKUP(B5, 'Consolidated Sheet'!B:E, 4, FALSE) | G5: TRUE | H5: TRUE | I5: FALSE | J5: FALSE | K5: FALSE | L5: FALSE | M5: =COUNTIF(G5:L5, TRUE) * 100 -> 200 | N5: Yes | O5: 200 | P5: =M5-O5 -> 0
A6: =ROW(A5) -> 5 | B6: P006 | C6: =VLOOKUP(B6, 'Consolidated Sheet'!B:C, 2, FALSE) -> 12 | D6: Male | E6: Panjim | F6: =VLOOKUP(B6, 'Consolidated Sheet'!B:E, 4, FALSE) -> A+ | G6: TRUE | H6: FALSE | I6: FALSE | J6: TRUE | K6: TRUE | L6: TRUE | M6: =COUNTIF(G6:L6, TRUE) * 100 -> 400 | N6: Yes | O6: 400 | P6: =M6-O6 -> 0
A7: =ROW(A6) -> 6 | B7: P048 | C7: =VLOOKUP(B7, 'Consolidated Sheet'!B:C, 2, FALSE) -> 12 | D7: Male | E7: Margao | F7: =VLOOKUP(B7, 'Consolidated Sheet'!B:E, 4, FALSE) -> A- | G7: TRUE | H7: FALSE | I7: FALSE | J7: TRUE | K7: TRUE | L7: TRUE | M7: =COUNTIF(G7:L7, TRUE) * 100 -> 400 | N7: Yes | O7: 400 | P7: =M7-O7 -> 0
A8: =ROW(A7) -> 7 | B8: P016 | C8: 12 | D8: Male | E8: Margao | F8: =VLOOKUP(B8, 'Consolidated Sheet'!B:E, 4, FALSE) | G8: TRUE | H8: FALSE | I8: FALSE | J8: TRUE | K8: TRUE | L8: FALSE | M8: =COUNTIF(G8:L8, TRUE) * 100 -> 300 | N8: Yes | O8: 300 | P8: =M8-O8 -> 0
A9: =ROW(A8) -> 8 | B9: P049 | C9: 13 | D9: Female | E9: Panjim | F9: =VLOOKUP(B9, 'Consolidated Sheet'!B:E, 4, FALSE) -> B+ | G9: FALSE | H9: FALSE | I9: FALSE | J9: FALSE | K9: FALSE | L9: TRUE | M9: =COUNTIF(G9:L9, TRUE) * 100 -> 100 | N9: Yes | O9: 100 | P9: =M9-O9 -> 0
A10: =ROW(A9) -> 9 | B10: P005 | C10: =VLOOKUP(B10, 'Consolidated Sheet'!B:C, 2, FALSE) -> 15 | D10: Male | E10: Panjim | F10: =VLOOKUP(B10, 'Consolidated Sheet'!B:E, 4, FALSE) -> O+ | G10: TRUE | H10: FALSE | I10: FALSE | J10: TRUE | K10: TRUE | L10: TRUE | M10: =COUNTIF(G10:L10, TRUE) * 100 -> 400 | N10: Yes | O10: 400 | P10: =M10-O10 -> 0
A11: =ROW(A10) -> 10 | B11: P050 | C11: =VLOOKUP(B11, 'Consolidated Sheet'!B:C, 2, FALSE) -> 15 | D11: Male | E11: Panjim | F11: =VLOOKUP(B11, 'Consolidated Sheet'!B:E, 4, FALSE) -> A+ | G11: FALSE | H11: FALSE | I11: FALSE | J11: TRUE | K11: TRUE | L11: TRUE | M11: =COUNTIF(G11:L11, TRUE) * 100 -> 300 | N11: Yes | O11: 300 | P11: =M11-O11 -> 0
A12: =ROW(A11) -> 11 | B12: P003 | C12: =VLOOKUP(B12, 'Consolidated Sheet'!B:C, 2, FALSE) -> 15 | D12: Female | E12: Margao | F12: =VLOOKUP(B12, 'Consolidated Sheet'!B:E, 4, FALSE) -> O+ | G12: TRUE | H12: FALSE | I12: FALSE | J12: FALSE | K12: FALSE | L12: TRUE | M12: =COUNTIF(G12:L12, TRUE) * 100 -> 200 | N12: Yes | O12: 200 | P12: =M12-O12 -> 0
A13: =ROW(A12) -> 12 | B13: P012 | C13: =VLOOKUP(B13, 'Consolidated Sheet'!B:C, 2, FALSE) -> 15 | D13: Female | E13: Vasco | F13: =VLOOKUP(B13, 'Consolidated Sheet'!B:E, 4, FALSE) -> O+ | G13: TRUE | H13: FALSE | I13: FALSE | J13: FALSE | K13: FALSE | L13: TRUE | M13: =COUNTIF(G13:L13, TRUE) * 100 -> 200 | N13: Yes | O13: 200 | P13: =M13-O13 -> 0
A14: =ROW(A13) -> 13 | B14: P007 | C14: =VLOOKUP(B14, 'Consolidated Sheet'!B:C, 2, FALSE) -> 16 | D14: Male | E14: Margao | F14: =VLOOKUP(B14, 'Consolidated Sheet'!B:E, 4, FALSE) | G14: TRUE | H14: FALSE | I14: FALSE | J14: TRUE | K14: TRUE | L14: FALSE | M14: =COUNTIF(G14:L14, TRUE) * 100 -> 300 | N14: Yes | O14: 300 | P14: =M14-O14 -> 0
A15: =ROW(A14) -> 14 | B15: P004 | C15: =VLOOKUP(B15, 'Consolidated Sheet'!B:C, 2, FALSE) -> 16 | D15: Female | E15: Margao | F15: =VLOOKUP(B15, 'Consolidated Sheet'!B:E, 4, FALSE) | G15: TRUE | H15: FALSE | I15: FALSE | J15: FALSE | K15: FALSE | L15: FALSE | M15: =COUNTIF(G15:L15, TRUE) * 100 -> 100 | N15: Yes | O15: 100 | P15: =M15-O15 -> 0
A16: =ROW(A15) -> 15 | B16: P014 | C16: 17 | D16: Male | E16: Panjim | F16: =VLOOKUP(B16, 'Consolidated Sheet'!B:E, 4, FALSE) | G16: TRUE | H16: TRUE | I16: FALSE | J16: FALSE | K16: FALSE | L16: FALSE | M16: =COUNTIF(G16:L16, TRUE) * 100 -> 200 | N16: Yes | O16: 200 | P16: =M16-O16 -> 0
A17: =ROW(A16) -> 16 | B17: P009 | C17: =VLOOKUP(B17, 'Consolidated Sheet'!B:C, 2, FALSE) -> 17 | D17: Male | E17: Vasco | F17: =VLOOKUP(B17, 'Consolidated Sheet'!B:E, 4, FALSE) | G17: TRUE | H17: FALSE | I17: FALSE | J17: TRUE | K17: FALSE | L17: TRUE | M17: =COUNTIF(G17:L17, TRUE) * 100 -> 300 | N17: Yes | O17: 300 | P17: =M17-O17 -> 0
A18: =ROW(A17) -> 17 | B18: P008 | C18: =VLOOKUP(B18, 'Consolidated Sheet'!B:C, 2, FALSE) -> 17 | D18: Male | E18: Margao | F18: =VLOOKUP(B18, 'Consolidated Sheet'!B:E, 4, FALSE) -> AB+ | G18: FALSE | H18: FALSE | I18: FALSE | J18: TRUE | K18: FALSE | L18: FALSE | M18: =COUNTIF(G18:L18, TRUE) * 100 -> 100 | N18: Yes | O18: 100 | P18: =M18-O18 -> 0
A19: =ROW(A18) -> 18 | B19: P030 | C19: =VLOOKUP(B19, 'Consolidated Sheet'!B:C, 2, FALSE) -> 18 | D19: Male | E19: Margao | F19: =VLOOKUP(B19, 'Consolidated Sheet'!B:E, 4, FALSE) -> O+ | G19: TRUE | H19: TRUE | I19: FALSE | J19: TRUE | K19: TRUE | L19: FALSE | M19: =COUNTIF(G19:L19, TRUE) * 100 -> 400 | N19: Yes | O19: 400 | P19: =M19-O19 -> 0
A20: =ROW(A19) -> 19 | B20: P036 | C20: =VLOOKUP(B20, 'Consolidated Sheet'!B:C, 2, FALSE) -> 18 | D20: Male | E20: Margao | F20: =VLOOKUP(B20, 'Consolidated Sheet'!B:E, 4, FALSE) -> AB+ | G20: TRUE | H20: FALSE | I20: FALSE | J20: TRUE | K20: FALSE | L20: FALSE | M20: =COUNTIF(G20:L20, TRUE) * 100 -> 200 | N20: Yes | O20: 200 | P20: =M20-O20 -> 0
A21: =ROW(A20) -> 20 | B21: P038 | C21: =VLOOKUP(B21, 'Consolidated Sheet'!B:C, 2, FALSE) -> 19 | D21: Male | E21: Vasco | F21: =VLOOKUP(B21, 'Consolidated Sheet'!B:E, 4, FALSE) | G21: TRUE | H21: TRUE | I21: FALSE | J21: FALSE | K21: FALSE | L21: FALSE | M21: =COUNTIF(G21:L21, TRUE) * 100 -> 200 | N21: Yes | O21: 200 | P21: =M21-O21 -> 0
A22: =ROW(A21) -> 21 | B22: P051 | C22: =VLOOKUP(B22, 'Consolidated Sheet'!B:C, 2, FALSE) -> 21 | D22: Male | E22: Margao | F22: =VLOOKUP(B22, 'Consolidated Sheet'!B:E, 4, FALSE) -> B+ | G22: TRUE | H22: TRUE | I22: FALSE | J22: TRUE | K22: TRUE | L22: FALSE | M22: =COUNTIF(G22:L22, TRUE) * 100 -> 400 | N22: Yes | O22: 400 | P22: =M22-O22 -> 0
A23: =ROW(A22) -> 22 | B23: P027 | C23: =VLOOKUP(B23, 'Consolidated Sheet'!B:C, 2, FALSE) -> 22 | D23: Female | E23: Panjim | F23: =VLOOKUP(B23, 'Consolidated Sheet'!B:E, 4, FALSE) -> B+ | G23: TRUE | H23: FALSE | I23: FALSE | J23: FALSE | K23: FALSE | L23: FALSE | M23: =COUNTIF(G23:L23, TRUE) * 100 -> 100 | N23: Yes | O23: 100 | P23: =M23-O23 -> 0
A24: =ROW(A23) -> 23 | B24: P052 | C24: =VLOOKUP(B24, 'Consolidated Sheet'!B:C, 2, FALSE) -> 24 | D24: Male | E24: Margao | F24: =VLOOKUP(B24, 'Consolidated Sheet'!B:E, 4, FALSE) -> AB- | G24: FALSE | H24: FALSE | I24: FALSE | J24: FALSE | K24: TRUE | L24: FALSE | M24: =COUNTIF(G24:L24, TRUE) * 100 -> 100 | N24: Yes | O24: 100 | P24: =M24-O24 -> 0
A25: =ROW(A24) -> 24 | B25: P032 | C25: =VLOOKUP(B25, 'Consolidated Sheet'!B:C, 2, FALSE) -> 25 | D25: Male | E25: Margao | F25: =VLOOKUP(B25, 'Consolidated Sheet'!B:E, 4, FALSE) | G25: TRUE | H25: FALSE | I25: FALSE | J25: TRUE | K25: TRUE | L25: FALSE | M25: =COUNTIF(G25:L25, TRUE) * 100 -> 300 | N25: Yes | O25: 300 | P25: =M25-O25 -> 0
A26: =ROW(A25) -> 25 | B26: P020 | C26: =VLOOKUP(B26, 'Consolidated Sheet'!B:C, 2, FALSE) -> 25 | D26: Male | E26: Margao | F26: =VLOOKUP(B26, 'Consolidated Sheet'!B:E, 4, FALSE) | G26: FALSE | H26: TRUE | I26: FALSE | J26: TRUE | K26: FALSE | L26: FALSE | M26: =COUNTIF(G26:L26, TRUE) * 100 -> 200 | N26: Yes | O26: 200 | P26: =M26-O26 -> 0
A27: =ROW(A26) -> 26 | B27: P033 | C27: =VLOOKUP(B27, 'Consolidated Sheet'!B:C, 2, FALSE) -> 26 | D27: Male | E27: Margao | F27: =VLOOKUP(B27, 'Consolidated Sheet'!B:E, 4, FALSE) | G27: TRUE | H27: TRUE | I27: FALSE | J27: FALSE | K27: TRUE | L27: FALSE | M27: =COUNTIF(G27:L27, TRUE) * 100 -> 300 | N27: Yes | O27: 300 | P27: =M27-O27 -> 0
A28: =ROW(A27) -> 27 | B28: P028 | C28: =VLOOKUP(B28, 'Consolidated Sheet'!B:C, 2, FALSE) -> 27 | D28: Female | E28: Panjim | F28: =VLOOKUP(B28, 'Consolidated Sheet'!B:E, 4, FALSE) | G28: TRUE | H28: FALSE | I28: FALSE | J28: TRUE | K28: FALSE | L28: FALSE | M28: =COUNTIF(G28:L28, TRUE) * 100 -> 200 | N28: Yes | O28: 200 | P28: =M28-O28 -> 0
... A41: =ROW(A40) -> 40 | B41: P001 | C41: =VLOOKUP(B41, 'Consolidated Sheet'!B:C, 2, FALSE) -> 8 | D41: Male | E41: Margao | F41: =VLOOKUP(B41, 'Consolidated Sheet'!B:E, 4, FALSE) | G41: TRUE | H41: TRUE | I41: FALSE | J41: FALSE | K41: FALSE | L41: FALSE | M41: =COUNTIF(G41:L41, TRUE) * 100 -> 200 | N41: Yes | O41: 200 | P41: =M41-O41 -> 0
A42: =ROW(A41) -> 41 | B42: P019 | D42: Male | E42: Vasco | F42: =VLOOKUP(B42, 'Consolidated Sheet'!B:E, 4, FALSE) | G42: TRUE | H42: TRUE | I42: FALSE | J42: FALSE | K42: TRUE | L42: FALSE | M42: =COUNTIF(G42:L42, TRUE) * 100 -> 300 | N42: Yes | O42: 300 | P42: =M42-O42 -> 0
A43: =ROW(A42) -> 42 | B43: P010 | C43: =VLOOKUP(B43, 'Consolidated Sheet'!B:C, 2, FALSE) -> 15 | D43: Male | E43: Vasco | F43: =VLOOKUP(B43, 'Consolidated Sheet'!B:E, 4, FALSE) | G43: TRUE | H43: FALSE | I43: FALSE | J43: TRUE | K43: FALSE | L43: FALSE | M43: =COUNTIF(G43:L43, TRUE) * 100 -> 200 | N43: Yes | O43: 200 | P43: =M43-O43 -> 0
A44: =ROW(A43) -> 43 | B44: P045 | C44: =VLOOKUP(B44, 'Consolidated Sheet'!B:C, 2, FALSE) | D44: Female | E44: Margao | F44: =VLOOKUP(B44, 'Consolidated Sheet'!B:E, 4, FALSE) | G44: FALSE | H44: FALSE | I44: FALSE | J44: TRUE | K44: FALSE | L44: FALSE | M44: =COUNTIF(G44:L44, TRUE) * 100 -> 100 | N44: Yes | O44: 100 | P44: =M44-O44 -> 0
O45: =SUM(O2:O44) -> 9800 | P45: =SUM(P3:P43) -> 0

Sheet Expenses
B1: Item | C1: Cost | D1: To Pay
B2: Lunch | C2: 5500 | D2: 500 paid from fees, 5000 paid from ysb fund
B3: Sanwiches | C3: 1400 | D3: Paid from fees
B4: Court | C4: 6000
B5: Certificates | C5: 1280 | D5: Paid from fees
B6: Medical | C6: 518 | D6: Paid from fees
B7: TT Balls & Shuttle Cock | C7: 2450 | D7: 1750 paid from fees, 300 Ayush fees adjusted.
B8: Water | C8: 240 | D8: Paid from fees
B9: Ice | C9: 120 | D9: Paid from fees
B10: Amul Cool | C10: 720 | D10: Paid by Chairman
B11: Paper plates & Spoons | C11: 240 | D11: Paid from fees
B16: Total Expense | C16: 18468
B17: Fees Received | C17: 9900
B18: Sponsor | C18: 5000
B20: Total Fees remainging in hand | C20: 2050 + 300 (pending)
